<?xml version="1.0"?>
<!-- Scara Robot -->
<robot name="scara_robot" xmlns:xacro="http://www.ros.org/wiki/xacro">
    <xacro:include filename="$(find scara_robot_description)/urdf/materials.xacro" />
    <xacro:include filename="$(find scara_robot_description)/urdf/scara_robot.gazebo" />
  
    
    <link name="world"/>    

    <joint name="joint0" type="fixed">
    <parent link="world"/>
    <child link="base_link"/>
    </joint>

    <link name="base_link">
        <visual>
             <origin xyz="0 0 0.1" rpy="0 0 0" />
             <geometry>
                <cylinder radius="0.1" length="0.2" />
             </geometry>
        </visual>

        <collision>
             <origin xyz="0 0 0.1" rpy="0 0 0"/>
             <geometry>
               <cylinder radius="0.1" length="0.2"/>
             </geometry>
        </collision>

        <inertial>
             <origin xyz="0 0 0.1" rpy="0 0 0"/>
             <mass value="20"/>
             <inertia ixx="100"  ixy="0"  ixz="0" iyy="100" iyz="0" izz="100" />
        </inertial>
    </link>

    <joint name="joint1" type="continuous">
        <origin xyz="0 0 0.2" rpy="0 0 0"/>
        <parent link="base_link"/>
        <child link="link1"/>
        <axis xyz="0 0 1 "/>
        <dynamics damping="0.7"/>
    </joint>

    <link name="link1">
        <visual>
             <origin xyz="0 0 0.1" rpy="0 0 0" />
             <geometry>
                <box size="0.1 0.1 0.2"/>
             </geometry>
         </visual>

        <collision>
             <origin xyz="0 0 0.1" rpy="0 0 0" />
             <geometry>
                <box size="0.1 0.1 0.2"/>
             </geometry>
        </collision>

        <inertial>
                <origin xyz="0 0 0.1" rpy="0 0 0"/>
             <mass value="10"/>
             <inertia ixx="100"  ixy="0"  ixz="0" iyy="100" iyz="0" izz="100" />
        </inertial>

    </link>
 
    
    <joint name="joint3" type="fixed">
        <parent link="link1"/>
        <child link="link2"/>
        <origin xyz="0 0 0.15" rpy="0 0 0"/>
        <axis xyz="0 0 1"/>
        <dynamics damping="0.7"/>
    </joint>


    <link name="link2">       

        <visual>
             <origin xyz="0 0.1 0.1" rpy="1.57 0 0" />
             <geometry>
                <box size="0.1 0.1 0.3"/>
             </geometry>
                
        </visual>

        <collision>
             <origin xyz="0 0.1 0.1" rpy="1.57 0 0" />
             <geometry>
                <box size="0.1 0.1 0.3"/>
             </geometry>
        </collision>

        <inertial>
             <origin xyz="0 0.1 0.1" rpy="1.57 0 0" />
             <mass value="0.5"/>
             <inertia ixx="10"  ixy="0"  ixz="0" iyy="10" iyz="0" izz="10" />
        </inertial>

    </link>

    <joint name="joint2" type="continuous">
        <parent link="link2"/>
        <child link="link3"/>
        <origin xyz="0 0.2 0.15" rpy="0 0 0"/>
        <axis xyz="0 0 1"/>
        <dynamics damping="0.7"/>     
    </joint>

    <link name="link3">
        <visual>
             <origin xyz="0 0.15 0.05" rpy="0 0 0" />
             <geometry>
                <box size="0.1 0.4 0.1"/>
             </geometry>
        </visual>

        <collision>
             <origin xyz="0 0.15 0.05" rpy="0 0 0" />
             <geometry>
                <box size="0.1 0.4 0.1"/>
             </geometry>
        </collision>

        <inertial>
             <origin xyz="0 0.15 0.05" rpy="0 0 0" />
             <mass value="0.5"/>
             <inertia ixx="10"  ixy="0"  ixz="0" iyy="10" iyz="0" izz="10" />
        </inertial>

    </link>

    <joint name="joint4" type="prismatic">
        <parent link="link3"/>
        <child link="link4"/>
        <origin xyz="0 0.35 -0.02" rpy="0 0 0"/>
        <axis xyz="0 0 -1"/>
        <dynamics damping="0.7"/>
        <limit
            lower="0.0" 
            upper="0.5"
            effort="10"
            velocity="10"   />
    </joint>

    <link name="link4">
        <visual>    
             <origin xyz="0 0 0.25" rpy="0 0 0" />
             <geometry>
                <cylinder radius="0.01" length="0.5" />
             </geometry>
        </visual>

        <collision>
             <origin xyz="0 0 0.25" rpy="0 0 0" />
             <geometry>
                <cylinder radius="0.01" length="0.6" />
             </geometry>
        </collision>

        <inertial>
             <origin xyz="0 0 -0.01" rpy="0 0 0"/>
             <mass value="0.5"/>
             <inertia ixx="1"  ixy="0"  ixz="0" iyy="1" iyz="0" izz="1" />
        </inertial>
    </link>

    <transmission name="tran1">
    <type>transmission_interface/SimpleTransmission</type>
    <joint name="joint1">
      <hardwareInterface>hardware_interface/EffortJointInterface</hardwareInterface>
    </joint>
    <actuator name="motor1">
      <hardwareInterface>hardware_interface/EffortJointInterface</hardwareInterface>
      <mechanicalReduction>1</mechanicalReduction>
    </actuator>
  </transmission>
  

<transmission name="tran2">
    <type>transmission_interface/SimpleTransmission</type>
    <joint name="joint2">
      <hardwareInterface>hardware_interface/EffortJointInterface</hardwareInterface>
    </joint>
    <actuator name="motor2">
      <hardwareInterface>hardware_interface/EffortJointInterface</hardwareInterface>
      <mechanicalReduction>1</mechanicalReduction>
    </actuator>
  </transmission>

  <transmission name="tran3">
    <type>transmission_interface/SimpleTransmission</type>
    <joint name="joint4">
      <hardwareInterface>hardware_interface/EffortJointInterface</hardwareInterface>
    </joint>
    <actuator name="motor4">
      <hardwareInterface>hardware_interface/EffortJointInterface</hardwareInterface>
      <mechanicalReduction>1</mechanicalReduction>
    </actuator>
  </transmission>

</robot>
